Workbook

Sheet FORM
A1: PAGE 1
A2: client name | C2: ='PAGE 1'!B1
A3: coordinate | C3: =('PAGE 1'!B2)&('PAGE 1'!C2)
A4: short address | C4: ='PAGE 1'!B3
A5: PAGE 2
A6: Orientation #1 | C6: Orientation #2 | E6: Orientation #3 | G6: Orientation #4
A7: Titl/Azimut | B7: =PAGE2!B9 | C7: Titl/Azimut | D7: =PAGE2!D9 | E7: Titl/Azimut | F7: =PAGE2!F9 | G7: Titl/Azimut | H7: =PAGE2!I9
A8: Pv Array | C8: Inverters | E8: Battery pack
A9: no of modules | B9: =SUM(GlobHor_DiffHor!D3:D6) | C9: Nb. Of units | D9: 1 | E9: nb. Of units | F9: 1
A10: pnom total | B10: =GlobHor_DiffHor!H3 | C10: total power | D10: =5 | E10: voltage | F10: =51
C11: pnomr ratio | D11: =B10/D10 | E11: capacity | F11: =F9*314
A12: Results summary
A13: Produced energy | B13: =GlobHor_DiffHor!O23
A14: user energy | B14: =GlobHor_DiffHor!Q23
A15: specific production | B15: =B13/B10
A16: Perf Ratio PR | B16: =GlobHor_DiffHor!T23*100
A17: Solar fraction SF | B17: =GlobHor_DiffHor!R23/GlobHor_DiffHor!Q23*100
A18: PAGE 3
A19: Storage | B19: Self consumption
A20: Jan | B20: =GlobHor_DiffHor!Q11 | D20: =GlobHor_DiffHor!Q16 | F20: =GlobHor_DiffHor!Q22
A21: Feb | B21: =GlobHor_DiffHor!Q12 | D21: =GlobHor_DiffHor!Q17 | F21: =GlobHor_DiffHor!Q22
A22: March | B22: =GlobHor_DiffHor!Q13 | D22: =GlobHor_DiffHor!Q18 | F22: =GlobHor_DiffHor!Q23
A23: April | B23: =GlobHor_DiffHor!Q14 | D23: =GlobHor_DiffHor!Q19
A24: May | B24: =GlobHor_DiffHor!Q15 | D24: =GlobHor_DiffHor!Q20
A25: PV Array Characteristics
A26: Manufacturer | C26: ='PAGE 3'!B14 | D26: Manufacturer | G26: ='PAGE 3'!D14
A27: Model | C27: ='PAGE 3'!B15 | D27: Model | G27: ='PAGE 3'!D15
A28: (Custom parameters definition) | C28: ='PAGE 3'!B16 | D28: (Custom parameters definition)
A29: Unit Nom. Power | C29: ='PAGE 3'!B17 | D29: Unit Nom. Power | G29: ='PAGE 3'!D17
A30: Array #1 - PV Array
A31: Orientation | B31: ='PAGE 3'!B20 | C31: Number of inverters | D31: =ROUND(B34/(B10*1000)*100,0) | E31: =D31/100
A32: Tilt/Azimuth | B32: ='PAGE 3'!B21 | C32: Total power | D32: ='PAGE 3'!D23
A33: Number of PV modules | B33: ='PAGE 3'!B22
A34: Nominal (STC) | B34: ='PAGE 3'!B23 | C34: Operating voltage | D34: ='PAGE 3'!D25
A35: Modules | B35: ='PAGE 3'!B24
A36: At operating cond. (50°C) | C36: Pnom ratio | D36: ='PAGE 3'!D26
A37: Pmpp | B37: ='PAGE 3'!B26
A38: U mpp | B38: ='PAGE 3'!B27
A39: I mpp | B39: ='PAGE 3'!B28
A40: Array #2 - PV Array
...

Sheet GlobHor_DiffHor
N1: INPUT | O1: Value | P1: Unit
C2: Orientation | D2: No. Panel | E2: TF | G2: INPUT | H2: Value | I2: Unit | N2: P50 Annual Production | O2: =O23 | P2: kWh/year
C3: Ori 1 | D3: ='PAGE 3'!B22 | E3: 0.97 | G3: PV Size | H3: =PAGE2!B14 | I3: kWp | N3: Year-to-Year Weather Variability | O3: ='PAGE 7'!B2/100 | P3: % | R3: Soiling & Mismatch Uncertainty | U3: 0.01 | V3: %
C4: Ori 2 | D4: ='PAGE 3'!B32 | E4: 0.95 | N4: PV Module Uncertainty | O4: 0.01 | P4: % | R4: Degradation Uncertainty | U4: 0.01 | V4: %
C5: Ori 3 | D5: ='PAGE 3'!B42 | E5: 0.97 | G5: Optical Loss | H5: 0.05 | I5: % | N5: Inverter Efficiency Uncertainty | O5: 0.005 | P5: % | R5: Customer Variability | U5: =O3 | V5: %
C6: Ori 4 | D6: ='PAGE 3'!B52 | E6: 0.97 | G6: Annual Load | H6: ='PAGE 1'!B6 | I6: kWh/year | N6: Soiling & Mismatch Uncertainty | O6: 0.01 | P6: %
N7: Degradation Uncertainty | O7: 0.01 | P7: %
N8: Customer Variability | O8: =O3 | P8: %
A9: Input / Month | B9: GlobHor | C9: Monthly % | D9: GlobHor | E9: Diffuse Ratio | F9: DiffHor | G9: T_Amb (°C) | H9: Ori1 GlobInc | I9: Ori2 GlobInc | J9: Ori3 GlobInc | K9: Ori4 GlobInc | L9: GlobInc | M9: GlobEff | N9: Monthly Performance Factor | O9: EArray | P9: Split % | Q9: E_User | R9: E_Solar | S9: E_Grid | T9: PR Ratio | U9: EFrGrid
A10: YEAR INPUT | B10: ='PAGE 1'!B5
A11: Jan | C11: 0.08 | D11: =$B$10*C11 | E11: 0.55 | F11: =D11*E11 | G11: 27.5 | H11: =D11*$E$3 | I11: =D11*$E$4 | J11: =D11*$E$5 | K11: =D11*$E$6 | L11: =((H11*$D$3)+(I11*$D$4)+(J11*$D$5)+(K11*$D$6))/SUM($D$3:$D$6) | M11: =L11*(1-$H$5) | N11: =ROUND(0.99*(1-(IFERROR('PAGE 4'!$B$9,1.5)/100)*1.8)*(1-0.0035*G11)*(1-MAX(0,(IFERROR('PAGE2'!$D$15,1.2)-1.1)*0.15)),3) | O11: =M11*$H$3*$N$11 | P11: 0.08 | Q11: =$H$6*P11 | R11: =MIN(O11,Q11) | S11: =MAX(O11-R11,0) | T11: =O11/(M11*$H$3) | U11: =MAX(Q11-R11,0)
A12: Feb | C12: 0.07 | D12: =$B$10*C12 | E12: 0.52 | F12: =D12*E12 | G12: 27.8 | H12: =D12*$E$3 | I12: =D12*$E$4 | J12: =D12*$E$5 | K12: =D12*$E$6 | L12: =((H12*$D$3)+(I12*$D$4)+(J12*$D$5)+(K12*$D$6))/SUM($D$3:$D$6) | M12: =L12*(1-$H$5) | N12: =ROUND(0.99*(1-(IFERROR('PAGE 4'!$B$9,1.5)/100)*1.8)*(1-0.0035*G12)*(1-MAX(0,(IFERROR('PAGE2'!$D$15,1.2)-1.1)*0.15)),3) | O12: =M12*$H$3*$N$12 | P12: 0.075 | Q12: =$H$6*P12 | R12: =MIN(O12,Q12) | S12: =MAX(O12-R12,0) | T12: =O12/(M12*$H$3) | U12: =MAX(Q12-R12,0)
A13: Mar | C13: 0.06 | D13: =$B$10*C13 | E13: 0.48 | F13: =D13*E13 | G13: 28.2 | H13: =D13*$E$3 | I13: =D13*$E$4 | J13: =D13*$E$5 | K13: =D13*$E$6 | L13: =((H13*$D$3)+(I13*$D$4)+(J13*$D$5)+(K13*$D$6))/SUM($D$3:$D$6) | M13: =L13*(1-$H$5) | N13: =ROUND(0.99*(1-(IFERROR('PAGE 4'!$B$9,1.5)/100)*1.8)*(1-0.0035*G13)*(1-MAX(0,(IFERROR('PAGE2'!$D$15,1.2)-1.1)*0.15)),3) | O13: =M13*$H$3*$N$13 | P13: 0.08 | Q13: =$H$6*P13 | R13: =MIN(O13,Q13) | S13: =MAX(O13-R13,0) | T13: =O13/(M13*$H$3) | U13: =MAX(Q13-R13,0)
A14: Apr | C14: 0.09 | D14: =$B$10*C14 | E14: 0.5 | F14: =D14*E14 | G14: 28.5 | H14: =D14*$E$3 | I14: =D14*$E$4 | J14: =D14*$E$5 | K14: =D14*$E$6 | L14: =((H14*$D$3)+(I14*$D$4)+(J14*$D$5)+(K14*$D$6))/SUM($D$3:$D$6) | M14: =L14*(1-$H$5) | N14: =ROUND(0.99*(1-(IFERROR('PAGE 4'!$B$9,1.5)/100)*1.8)*(1-0.0035*G14)*(1-MAX(0,(IFERROR('PAGE2'!$D$15,1.2)-1.1)*0.15)),3) | O14: =M14*$H$3*$N$14 | P14: 0.085 | Q14: =$H$6*P14 | R14: =MIN(O14,Q14) | S14: =MAX(O14-R14,0) | T14: =O14/(M14*$H$3) | U14: =MAX(Q14-R14,0)
A15: May | C15: 0.08 | D15: =$B$10*C15 | E15: 0.53 | F15: =D15*E15 | G15: 28.8 | H15: =D15*$E$3 | I15: =D15*$E$4 | J15: =D15*$E$5 | K15: =D15*$E$6 | L15: =((H15*$D$3)+(I15*$D$4)+(J15*$D$5)+(K15*$D$6))/SUM($D$3:$D$6) | M15: =L15*(1-$H$5) | N15: =ROUND(0.99*(1-(IFERROR('PAGE 4'!$B$9,1.5)/100)*1.8)*(1-0.0035*G15)*(1-MAX(0,(IFERROR('PAGE2'!$D$15,1.2)-1.1)*0.15)),3) | O15: =M15*$H$3*$N$15 | P15: 0.09 | Q15: =$H$6*P15 | R15: =MIN(O15,Q15) | S15: =MAX(O15-R15,0) | T15: =O15/(M15*$H$3) | U15: =MAX(Q15-R15,0)
A16: Jun | C16: 0.09 | D16: =$B$10*C16 | E16: 0.49 | F16: =D16*E16 | G16: 28.9 | H16: =D16*$E$3 | I16: =D16*$E$4 | J16: =D16*$E$5 | K16: =D16*$E$6 | L16: =((H16*$D$3)+(I16*$D$4)+(J16*$D$5)+(K16*$D$6))/SUM($D$3:$D$6) | M16: =L16*(1-$H$5) | N16: =ROUND(0.99*(1-(IFERROR('PAGE 4'!$B$9,1.5)/100)*1.8)*(1-0.0035*G16)*(1-MAX(0,(IFERROR('PAGE2'!$D$15,1.2)-1.1)*0.15)),3) | O16: =M16*$H$3*$N$16 | P16: 0.095 | Q16: =$H$6*P16 | R16: =MIN(O16,Q16) | S16: =MAX(O16-R16,0) | T16: =O16/(M16*$H$3) | U16: =MAX(Q16-R16,0)
A17: Jul | C17: 0.08 | D17: =$B$10*C17 | E17: 0.45 | F17: =D17*E17 | G17: 28.7 | H17: =D17*$E$3 | I17: =D17*$E$4 | J17: =D17*$E$5 | K17: =D17*$E$6 | L17: =((H17*$D$3)+(I17*$D$4)+(J17*$D$5)+(K17*$D$6))/SUM($D$3:$D$6) | M17: =L17*(1-$H$5) | N17: =ROUND(0.99*(1-(IFERROR('PAGE 4'!$B$9,1.5)/100)*1.8)*(1-0.0035*G17)*(1-MAX(0,(IFERROR('PAGE2'!$D$15,1.2)-1.1)*0.15)),3) | O17: =M17*$H$3*$N$17 | P17: 0.09 | Q17: =$H$6*P17 | R17: =MIN(O17,Q17) | S17: =MAX(O17-R17,0) | T17: =O17/(M17*$H$3) | U17: =MAX(Q17-R17,0)
A18: Aug | C18: 0.08 | D18: =$B$10*C18 | E18: 0.46 | F18: =D18*E18 | G18: 28.6 | H18: =D18*$E$3 | I18: =D18*$E$4 | J18: =D18*$E$5 | K18: =D18*$E$6 | L18: =((H18*$D$3)+(I18*$D$4)+(J18*$D$5)+(K18*$D$6))/SUM($D$3:$D$6) | M18: =L18*(1-$H$5) | N18: =ROUND(0.99*(1-(IFERROR('PAGE 4'!$B$9,1.5)/100)*1.8)*(1-0.0035*G18)*(1-MAX(0,(IFERROR('PAGE2'!$D$15,1.2)-1.1)*0.15)),3) | O18: =M18*$H$3*$N$18 | P18: 0.085 | Q18: =$H$6*P18 | R18: =MIN(O18,Q18) | S18: =MAX(O18-R18,0) | T18: =O18/(M18*$H$3) | U18: =MAX(Q18-R18,0)
A19: Sep | C19: 0.09 | D19: =$B$10*C19 | E19: 0.5 | F19: =D19*E19 | G19: 28.3 | H19: =D19*$E$3 | I19: =D19*$E$4 | J19: =D19*$E$5 | K19: =D19*$E$6 | L19: =((H19*$D$3)+(I19*$D$4)+(J19*$D$5)+(K19*$D$6))/SUM($D$3:$D$6) | M19: =L19*(1-$H$5) | N19: =ROUND(0.99*(1-(IFERROR('PAGE 4'!$B$9,1.5)/100)*1.8)*(1-0.0035*G19)*(1-MAX(0,(IFERROR('PAGE2'!$D$15,1.2)-1.1)*0.15)),3) | O19: =M19*$H$3*$N$19 | P19: 0.08 | Q19: =$H$6*P19 | R19: =MIN(O19,Q19) | S19: =MAX(O19-R19,0) | T19: =O19/(M19*$H$3) | U19: =MAX(Q19-R19,0)
A20: Oct | C20: 0.08 | D20: =$B$10*C20 | E20: 0.55 | F20: =D20*E20 | G20: 28 | H20: =D20*$E$3 | I20: =D20*$E$4 | J20: =D20*$E$5 | K20: =D20*$E$6 | L20: =((H20*$D$3)+(I20*$D$4)+(J20*$D$5)+(K20*$D$6))/SUM($D$3:$D$6) | M20: =L20*(1-$H$5) | N20: =ROUND(0.99*(1-(IFERROR('PAGE 4'!$B$9,1.5)/100)*1.8)*(1-0.0035*G20)*(1-MAX(0,(IFERROR('PAGE2'!$D$15,1.2)-1.1)*0.15)),3) | O20: =M20*$H$3*$N$20 | P20: 0.08 | Q20: =$H$6*P20 | R20: =MIN(O20,Q20) | S20: =MAX(O20-R20,0) | T20: =O20/(M20*$H$3) | U20: =MAX(Q20-R20,0)
A21: Nov | C21: 0.06 | D21: =$B$10*C21 | E21: 0.62 | F21: =D21*E21 | G21: 27.7 | H21: =D21*$E$3 | I21: =D21*$E$4 | J21: =D21*$E$5 | K21: =D21*$E$6 | L21: =((H21*$D$3)+(I21*$D$4)+(J21*$D$5)+(K21*$D$6))/SUM($D$3:$D$6) | M21: =L21*(1-$H$5) | N21: =ROUND(0.99*(1-(IFERROR('PAGE 4'!$B$9,1.5)/100)*1.8)*(1-0.0035*G21)*(1-MAX(0,(IFERROR('PAGE2'!$D$15,1.2)-1.1)*0.15)),3) | O21: =M21*$H$3*$N$21 | P21: 0.075 | Q21: =$H$6*P21 | R21: =MIN(O21,Q21) | S21: =MAX(O21-R21,0) | T21: =O21/(M21*$H$3) | U21: =MAX(Q21-R21,0)
A22: Dec | C22: 0.07 | D22: =$B$10*C22 | E22: 0.6 | F22: =D22*E22 | G22: 27.5 | H22: =D22*$E$3 | I22: =D22*$E$4 | J22: =D22*$E$5 | K22: =D22*$E$6 | L22: =((H22*$D$3)+(I22*$D$4)+(J22*$D$5)+(K22*$D$6))/SUM($D$3:$D$6) | M22: =L22*(1-$H$5) | N22: =ROUND(0.99*(1-(IFERROR('PAGE 4'!$B$9,1.5)/100)*1.8)*(1-0.0035*G22)*(1-MAX(0,(IFERROR('PAGE2'!$D$15,1.2)-1.1)*0.15)),3) | O22: =M22*$H$3*$N$22 | P22: 0.085 | Q22: =$H$6*P22 | R22: =MIN(O22,Q22) | S22: =MAX(O22-R22,0) | T22: =O22/(M22*$H$3) | U22: =MAX(Q22-R22,0)
A23: YEAR TOTAL | D23: =SUM(D11:D22) | F23: =SUM(F11:F22) | G23: =AVERAGE(G11:G22) | H23: =D23*$E$3 | I23: =D23*$E$4 | J23: =D23*$E$5 | K23: =D23*$E$6 | L23: =((H23*$D$3)+(I23*$D$4)+(J23*$D$5)+(K23*$D$6))/SUM($D$3:$D$6) | M23: =SUM(M11:M22) | O23: =SUM(O11:O22) | Q23: =SUM(Q11:Q22) | R23: =SUM(R11:R22) | S23: =SUM(S11:S22) | T23: =SUM(O11:O22)/(SUM(M11:M22)*$H$3)*0.97 | U23: =SUM(U11:U22)
N25: System Uncertainty | O25: =SQRT(O4^2+O5^2+O6^2+O7^2+O8^2) | P25: % | T25: bulan kering: ±0.45–0.50
N26: Global Variability | O26: =SQRT(O3^2+O25^2) | P26: % | T26: bulan hujan: ±0.55–0.65
N27: Variability | O27: =O28*O26 | P27: kWh | T27: Lokasi | U27: GlobHor anggaran
N28: P50 | O28: =O23 | P28: kWh/year | T28: Kuala Lumpur | U28: ±1650–1700 kWh/m²/year
N29: P75 | O29: =O28-(0.674*O26*O28) | P29: kWh/year | T29: Penang | U29: ±1700–1800 kWh/m²/year
N30: P90 | O30: =O28-(1.282*O26*O28) | P30: kWh/year | T30: Johor | U30: ±1600–1700 kWh/m²/year
T31: Sabah/Sarawak | U31: boleh berbeza

Sheet PVsyst Graph Data
A1: PV SYST GRAPH DATA MASTER
A3: 1. IRRADIATION INPUT
A4: Global Horizontal Irradiation (GlobHor) | B4: =GlobHor_DiffHor!D23
A5: Global Incident in Collector Plane (GlobInc) | B5: =GlobHor_DiffHor!L23
A6: Effective Irradiation (GlobEff) | B6: =GlobHor_DiffHor!M23
A8: 2. PV ENERGY LOSS DIAGRAM
A9: PV Nominal Energy at STC (kWh) | B9: =GlobHor_DiffHor!O23
A10: Module Degradation Loss (%) | B10: 1
A11: Temperature Loss (%)
A12: Mismatch Loss (%)
A13: DC Wiring Loss (%) | B13: ='PAGE 4'!B9
A14: Array Virtual Energy at MPP | B14: =B9*(1-8.5%)
A15: Available Energy at Inverter Output | B15: =B14*(1-0.6%)
A16: Final Energy After AC Loss | B16: =B15*(1-2.64%)
A17: Final Energy After AC Loss (kWh)
A19: 3. ENERGY BALANCE (NO BATTERY)
A20: Direct Use / E_Solar (kWh) | B20: =GlobHor_DiffHor!R23*0.2
A21: Grid Export / E_Grid (kWh) | B21: =GlobHor_DiffHor!S23
A22: Grid Import / EFrGrid (kWh) | B22: =GlobHor_DiffHor!U23
A24: 4. BATTERY OPTION
A25: Battery Capacity (kWh) | B25: =FORM!B80
A26: Usable Energy (kWh) | B26: =FORM!B81
A27: Max Charging Power (kW) | B27: =FORM!D77
A28: Max Discharging Power (kW) | B28: =FORM!D79
A29: Battery Stored Energy (kWh) | B29: =GlobHor_DiffHor!R23-B20
A30: Battery Discharged Energy (kWh)
A31: Battery Loss (kWh)
A33: 5. P50 P75 P90
A34: P50 Annual Production | B34: =FORM!B13
A35: P75
A36: P90

Sheet PAGE 1
A1: CLIENT NAME | B1: KHOR MEOW SWEE
A2: COORDINATE | B2: 5.182659 | C2: 100.48085
A3: SHORT ADDRESS | B3: 19, LORONG CENDERAWASIH INDAH 4
A5: YEAR INPUT | B5: 1800
A6: Annual Load | B6: 9600
A8: NOTES
A9: Lokasi | B9: GlobHor anggaran
A10: Selangor / Kuala Lumpur | B10: ±1650–1700 kWh/m²/year
A11: Utara | B11: ±1700–1800 kWh/m²/year
A12: Selatan | B12: ±1600–1700 kWh/m²/year
A13: Sabah/Sarawak | B13: boleh berbeza
A15: Apartment / kecil | B15: 3,000 – 5,000 kWh/year | C15: HIS MODEL
A16: Rumah biasa 1 tingkat | B16: 6,000 – 8,000 kWh/year
A17: Rumah teres besar | B17: 8,000 – 12,000 kWh/year | C17: HIT MODEL
A18: Semi-D | B18: 12,000 – 18,000 kWh/year
A19: Banglo | B19: 18,000 – 30,000 kWh/year

Sheet PAGE2
A1: PROJECT SUMMARY
A2: GEOGRAPHICAL SITE | B2: ='PAGE 1'!B3
A3: WEARTHER DATA | B3: ='PAGE 1'!B3
A4: LATITUDE | B4: ='PAGE 1'!B2
A5: LONGITUDE | B5: ='PAGE 1'!C2
A7: SYSTEM SUMMARY
A8: ORIENTATION #1 | C8: ORIENTATION #2 | E8: ORIENTATION #3 | H8: ORIENTATION #4
A9: TILT/AZIMUTH | B9: 20/180° | C9: TILT/AZIMUTH | D9: 20/180° | E9: TILT/AZIMUTH | F9: 20/180° | H9: TILT/AZIMUTH | I9: 20/180°
A11: System information
A12: PV Array | C12: Inverters | E12: Battery pack
A13: Nb.of modules | B13: 11 | C13: Nb.of units | D13: 1 | E13: Nb. Of units | F13: 1
A14: Pnom total | B14: =B13*'PAGE 3'!B17/1000 | C14: Total power | D14: 5 | E14: Voltage | F14: 51
C15: Pnom ratio | D15: =B14/D14 | E15: Capacity | F15: =F13*314
A17: Results summary
A18: Produced Energy | B18: =GlobHor_DiffHor!O23 | C18: Specific production | D18: =B18/PAGE2!B14 | E18: Perf. Ratio PR | F18: =GlobHor_DiffHor!T23*100
A19: Used Energy | B19: =GlobHor_DiffHor!Q23 | E19: Solar Fraction SF | F19: =GlobHor_DiffHor!R23/GlobHor_DiffHor!Q23*100

Sheet PAGE 3
A1: GENERAL PARAMETERS
A2: ORIENTATION #1 | C2: ORIENTATION #2 | E2: ORIENTATION #3 | H2: ORIENTATION #4
A3: TILT/AZIMUTH | B3: =PAGE2!B9 | C3: TILT/AZIMUTH | D3: =PAGE2!D9 | E3: TILT/AZIMUTH | F3: =PAGE2!F9 | H3: TILT/AZIMUTH | I3: =PAGE2!I9
A5: Self Consumption
A6: Jan | B6: =GlobHor_DiffHor!Q11 | C6: Jun | D6: =GlobHor_DiffHor!Q16 | E6: Nov. | F6: =GlobHor_DiffHor!Q21
A7: Feb | B7: =GlobHor_DiffHor!Q12 | C7: July | D7: =GlobHor_DiffHor!Q17 | E7: Dec. | F7: =GlobHor_DiffHor!Q22
A8: March | B8: =GlobHor_DiffHor!Q13 | C8: Aug. | D8: =GlobHor_DiffHor!Q18 | E8: Year | F8: =GlobHor_DiffHor!Q23
A9: April | B9: =GlobHor_DiffHor!Q14 | C9: Sept | D9: =GlobHor_DiffHor!Q19
A10: May | B10: =GlobHor_DiffHor!Q15 | C10: Oct | D10: =GlobHor_DiffHor!Q20
A12: PV Array Characteristics
A13: PV Module | C13: Inverter
A14: Manufacturer | B14: Astronergy | C14: Manufacturer | D14: Hoymiles
A15: Model | B15: CHSMM66RN(DG)/F-BH-630 | C15: Model | D15: HIS-5L-G3
A16: Custom parameters definition | B16: CHSMM66RN(DG)/F-BH-630.PAN
A17: Unit Nom. Power | B17: 630 | C17: Unit Nom. Power | D17: =PAGE2!D14
A19: Array #1 - PV Array
A20: Orientation | B20: 1
A21: Tilt/Azimuth | B21: =B3
A22: Number of PV modules | B22: 7 | C22: Number of inverters | D22: =FORM!D31 | E22: =FORM!E31
A23: Nominal (STC) | B23: =B22*B17 | C23: Total power | D23: =D17*D22/100
A24: Modules | B24: =B22 | D24: HIS Model | E24: HIT Model
A25: At operating cond. (50°C) | C25: Operating voltage | D25: 90-550 | E25: 150-990
A26: Pmpp | B26: =B22*588 | C26: Pnom ratio | D26: =PAGE2!D15 | E26: =PAGE2!D15
A27: U mpp | B27: =B22*37.7
A28: I mpp | B28: =IFERROR(B26/B27,0)
A29: Array #2- PV Array
A30: Orientation | B30: 1
A31: Tilt/Azimuth | B31: =D3
A32: Number of PV modules | B32: 7 | C32: Number of inverters | D32: =FORM!D41 | E32: =FORM!E41
A33: Nominal (STC) | B33: =B32*B17 | C33: Total power | D33: =D17*D32/100
A34: Modules | B34: =B32 | D34: HIS Model | E34: HIT Model
A35: At operating cond. (50°C) | C35: Operating voltage | D35: 90-550 | E35: 150-990
A36: Pmpp | B36: =B32*588 | C36: Pnom ratio | D36: =PAGE2!D15 | E36: =PAGE2!D15
A37: U mpp | B37: =B32*37.7
A38: I mpp | B38: =IFERROR(B36/B37,0)
A39: Array #3- PV Array
A40: Orientation | B40: 1
A41: Tilt/Azimuth | B41: =F3
A42: Number of PV modules | B42: 7 | C42: Number of inverters | D42: =FORM!D51 | E42: =FORM!E51
A43: Nominal (STC) | B43: =B42*B17 | C43: Total power | D43: =D17*D42/100
...

Sheet PAGE 4
A1: Grid storage - Self Consumption
A2: Battery pack | C2: Battery Input charger
A3: Nb. Of units | B3: =PAGE2!F13 | C3: Max. charging power | D3: =B4*157/1000
A4: voltage | B4: =PAGE2!F14 | C4: Battery to Grid Inverter
A5: Nominal Capacity (C10) | B5: =PAGE2!F15 | C5: Max. discharging power | D5: =51*314*0.5*0.95/1000
A6: Nominal energy | B6: 16.1
A8: DC wiring losses
A9: Loss Fraction | B9: =AVERAGE(B12,D12,B16,D16)
A10: Array #1 - PV Array (Length) | B10: 100 | C10: Array #2 - PV Array (Length) | D10: 90
A11: Global array res. | B11: =0.0175*B10/6*1000 | C11: Global array res. | D11: =0.0175*D10/6*1000
A12: Loss fraction | B12: =IFERROR(16^2*B11/1000/'PAGE 3'!B23*100,0) | C12: Loss fraction | D12: =IFERROR(16^2*D11/1000/'PAGE 3'!B33*100,0)
A14: Array #3 - PV Array (Length) | B14: 80 | C14: Array #4 - PV Array (Length) | D14: 60
A15: Global array res. | B15: =0.0175*B14/6*1000 | C15: Global array res. | D15: =0.0175*D14/6*1000
A16: Loss fraction | B16: =IFERROR(16^2*B15/1000/'PAGE 3'!B43*100,0) | C16: Loss fraction | D16: =IFERROR(16^2*D15/1000/'PAGE 3'!B53*100,0)
A18: AC wiring losses | B18: HIS Model | C18: HIT Model
A19: Inverter voltage | B19: 220 | C19: 400
A20: Global System | B20: HIS Model | C20: HIT Model
A21: Wire section | B21: 2x4 | C21: 3x3
A22: Wires length | B22: 10 | C22: 20

Sheet PAGE 5
A1: Main results
A2: System Production
A3: Produced energy | B3: =PAGE2!B18 | C3: Specific Production | D3: =PAGE2!D18
A4: User Energy | B4: =PAGE2!B19 | C4: Perf Ratio PR | D4: =PAGE2!F18
C5: Solar fraction SF | D5: =PAGE2!F19
A7: Balances and main results
B8: GlobHor | C8: DiffHor | D8: T_Amb | E8: GlobInc | F8: GlobEff | G8: Earray | H8: E_User | I8: E_Solar | J8: E_Grid | K8: EfrGrid
A9: Jan | B9: =GlobHor_DiffHor!D11 | C9: =GlobHor_DiffHor!F11 | D9: =GlobHor_DiffHor!G11 | E9: =GlobHor_DiffHor!L11 | F9: =GlobHor_DiffHor!M11 | G9: =GlobHor_DiffHor!O11 | H9: =GlobHor_DiffHor!Q11 | I9: =GlobHor_DiffHor!R11 | J9: =GlobHor_DiffHor!S11 | K9: =GlobHor_DiffHor!U11
A10: Feb | B10: =GlobHor_DiffHor!D12 | C10: =GlobHor_DiffHor!F12 | D10: =GlobHor_DiffHor!G12 | E10: =GlobHor_DiffHor!L12 | F10: =GlobHor_DiffHor!M12 | G10: =GlobHor_DiffHor!O12 | H10: =GlobHor_DiffHor!Q12 | I10: =GlobHor_DiffHor!R12 | J10: =GlobHor_DiffHor!S12 | K10: =GlobHor_DiffHor!U12
A11: March | B11: =GlobHor_DiffHor!D13 | C11: =GlobHor_DiffHor!F13 | D11: =GlobHor_DiffHor!G13 | E11: =GlobHor_DiffHor!L13 | F11: =GlobHor_DiffHor!M13 | G11: =GlobHor_DiffHor!O13 | H11: =GlobHor_DiffHor!Q13 | I11: =GlobHor_DiffHor!R13 | J11: =GlobHor_DiffHor!S13 | K11: =GlobHor_DiffHor!U13
A12: April | B12: =GlobHor_DiffHor!D14 | C12: =GlobHor_DiffHor!F14 | D12: =GlobHor_DiffHor!G14 | E12: =GlobHor_DiffHor!L14 | F12: =GlobHor_DiffHor!M14 | G12: =GlobHor_DiffHor!O14 | H12: =GlobHor_DiffHor!Q14 | I12: =GlobHor_DiffHor!R14 | J12: =GlobHor_DiffHor!S14 | K12: =GlobHor_DiffHor!U14
A13: May | B13: =GlobHor_DiffHor!D15 | C13: =GlobHor_DiffHor!F15 | D13: =GlobHor_DiffHor!G15 | E13: =GlobHor_DiffHor!L15 | F13: =GlobHor_DiffHor!M15 | G13: =GlobHor_DiffHor!O15 | H13: =GlobHor_DiffHor!Q15 | I13: =GlobHor_DiffHor!R15 | J13: =GlobHor_DiffHor!S15 | K13: =GlobHor_DiffHor!U15
A14: Jun | B14: =GlobHor_DiffHor!D16 | C14: =GlobHor_DiffHor!F16 | D14: =GlobHor_DiffHor!G16 | E14: =GlobHor_DiffHor!L16 | F14: =GlobHor_DiffHor!M16 | G14: =GlobHor_DiffHor!O16 | H14: =GlobHor_DiffHor!Q16 | I14: =GlobHor_DiffHor!R16 | J14: =GlobHor_DiffHor!S16 | K14: =GlobHor_DiffHor!U16
A15: July | B15: =GlobHor_DiffHor!D17 | C15: =GlobHor_DiffHor!F17 | D15: =GlobHor_DiffHor!G17 | E15: =GlobHor_DiffHor!L17 | F15: =GlobHor_DiffHor!M17 | G15: =GlobHor_DiffHor!O17 | H15: =GlobHor_DiffHor!Q17 | I15: =GlobHor_DiffHor!R17 | J15: =GlobHor_DiffHor!S17 | K15: =GlobHor_DiffHor!U17
A16: Aug. | B16: =GlobHor_DiffHor!D18 | C16: =GlobHor_DiffHor!F18 | D16: =GlobHor_DiffHor!G18 | E16: =GlobHor_DiffHor!L18 | F16: =GlobHor_DiffHor!M18 | G16: =GlobHor_DiffHor!O18 | H16: =GlobHor_DiffHor!Q18 | I16: =GlobHor_DiffHor!R18 | J16: =GlobHor_DiffHor!S18 | K16: =GlobHor_DiffHor!U18
A17: Sept | B17: =GlobHor_DiffHor!D19 | C17: =GlobHor_DiffHor!F19 | D17: =GlobHor_DiffHor!G19 | E17: =GlobHor_DiffHor!L19 | F17: =GlobHor_DiffHor!M19 | G17: =GlobHor_DiffHor!O19 | H17: =GlobHor_DiffHor!Q19 | I17: =GlobHor_DiffHor!R19 | J17: =GlobHor_DiffHor!S19 | K17: =GlobHor_DiffHor!U19
A18: Oct | B18: =GlobHor_DiffHor!D20 | C18: =GlobHor_DiffHor!F20 | D18: =GlobHor_DiffHor!G20 | E18: =GlobHor_DiffHor!L20 | F18: =GlobHor_DiffHor!M20 | G18: =GlobHor_DiffHor!O20 | H18: =GlobHor_DiffHor!Q20 | I18: =GlobHor_DiffHor!R20 | J18: =GlobHor_DiffHor!S20 | K18: =GlobHor_DiffHor!U20
A19: Nov. | B19: =GlobHor_DiffHor!D21 | C19: =GlobHor_DiffHor!F21 | D19: =GlobHor_DiffHor!G21 | E19: =GlobHor_DiffHor!L21 | F19: =GlobHor_DiffHor!M21 | G19: =GlobHor_DiffHor!O21 | H19: =GlobHor_DiffHor!Q21 | I19: =GlobHor_DiffHor!R21 | J19: =GlobHor_DiffHor!S21 | K19: =GlobHor_DiffHor!U21
A20: Dec. | B20: =GlobHor_DiffHor!D22 | C20: =GlobHor_DiffHor!F22 | D20: =GlobHor_DiffHor!G22 | E20: =GlobHor_DiffHor!L22 | F20: =GlobHor_DiffHor!M22 | G20: =GlobHor_DiffHor!O22 | H20: =GlobHor_DiffHor!Q22 | I20: =GlobHor_DiffHor!R22 | J20: =GlobHor_DiffHor!S22 | K20: =GlobHor_DiffHor!U22
A21: Year | B21: =GlobHor_DiffHor!D23 | C21: =GlobHor_DiffHor!F23 | D21: =GlobHor_DiffHor!G23 | E21: =GlobHor_DiffHor!L23 | F21: =GlobHor_DiffHor!M23 | G21: =GlobHor_DiffHor!O23 | H21: =GlobHor_DiffHor!Q23 | I21: =GlobHor_DiffHor!R23 | J21: =GlobHor_DiffHor!S23 | K21: =GlobHor_DiffHor!U23

Sheet PAGE 6
A1: Loss diagram
A3: GlobHor | B3: ='PAGE 5'!B21
A4: Globinc | B4: =GlobHor_DiffHor!L23
A5: Pv nominal | B5: =GlobHor_DiffHor!O23
A6: Array Virtual | B6: ='PVsyst Graph Data'!B14
A7: Final energy after ac loss | B7: ='PVsyst Graph Data'!B16
A8: Efr Grid | B8: =GlobHor_DiffHor!U23
A9: Battery Stored | B9: ='PVsyst Graph Data'!B29
A10: Direct uses | B10: =GlobHor_DiffHor!S23

Sheet PAGE 7
A1: P50=P90 evaluation | N1: NOTES
A2: Weather data | B2: 3.8 | N2: Negeri | O2: Assumption
A3: Year to year variability (Variance) | B3: 5.7 | N3: Perlis | O3: 0.035
N4: Kedah | O4: 0.035
A5: Annual production probility | N5: Pulau Pinang | O5: 0.037
A6: Variability | B6: =GlobHor_DiffHor!O27 | N6: Perak | O6: 0.035
A7: P50 | B7: =GlobHor_DiffHor!O28 | N7: Selangor | O7: 0.038
A8: P90 | B8: =GlobHor_DiffHor!O29 | N8: Kuala Lumpur | O8: 0.038
A9: P75 | B9: =GlobHor_DiffHor!O30 | N9: Putrajaya | O9: 0.038
N10: Negeri Sembilan | O10: 0.04
N11: Melaka | O11: 0.04
N12: Johor | O12: 0.031
N13: Pahang | O13: 0.042
N14: Terengganu | O14: 0.043
N15: Kelantan | O15: 0.043
N16: Sabah | O16: 0.045
N17: Sarawak | O17: 0.045
